Workbook

Sheet boitiers actifs
A1: Name | B1: Gateway | C1: Boitier | D1: License Plate | E1: VIN | F1: Driver | G1: Vehicle Type | H1: Gross Vehicle Weight | I1: Weight Unit | J1: Tags | K1: Site | L1: Odometer (km) | M1: Engine Hours | N1: Camera | O1: Camera Serial | P1: Multicam | Q1: Multicam Serial | R1: Battery | S1: Power State | T1: Install Photos | U1: Device Calibration Status | V1: Last Connected | W1: Last Location | X1: Wifi SSID | Y1: Wifi Up | Z1: Wifi IP | AA1: Wifi Access Point Data Usage (MB) | AB1: Cell Operator | AC1: Cell Up | AD1: Ethernet IP | AE1: Cable SKU | AF1: Ethernet Up | AG1: Vehicle Regulation Mode
A2: DW-773-YG | B2: VG54-EU | C2: m | D2: DW-773-YG | E2: VF640J567FB002628 | F2: n/a | G2: Truck | H2: 16000 | I2: KG | J2: TG CENTRE EST | K2: =VLOOKUP(J2, correspondance!A:B, 2, FALSE) -> TG CENTRE EST | L2: 592571.2 | M2: 11541 | N2: n/a | O2: n/a | P2: n/a | Q2: n/a | R2: n/a | S2: n/a | T2: n/a | U2: Calibrated | V2: 14 avr. 2026 10:01 | W2: D 37, Planchez, Bourgogne-Franche-Comté, 58230 | X2: n/a | Y2: n/a | Z2: n/a | AA2: 0 | AB2: F SFR | AC2: true | AD2: n/a | AE2: CBL-VG-CFMS | AF2: n/a | AG2: Regulated
A3: FR-281-MN | B3: VG54-EU | C3: GGMW-NMZ-NT6 | D3: FR-281-MN | E3: VF620J86XLB007983 | F3: n/a | G3: Truck | H3: 19000 | I3: KG | J3: TG La Roche sur Yon (PF) | K3: =VLOOKUP(J3, correspondance!A:B, 2, FALSE) -> TG La Roche sur Yon (PF) | L3: 341211.2 | M3: 9569 | N3: n/a | O3: n/a | P3: n/a | Q3: n/a | R3: n/a | S3: n/a | T3: n/a | U3: Calibrated | V3: 14 avr. 2026 10:01 | W3: Impasse des Ajoncs, La Roche-sur-Yon, Pays de la Loire, 85000 | X3: n/a | Y3: n/a | Z3: n/a | AA3: 0 | AB3: F SFR | AC3: true | AD3: n/a | AE3: CBL-VG-CHGV | AF3: n/a | AG3: Regulated
A4: FT-601-CN | B4: VG54-EU | C4: G4YX-EK6-Z7R | D4: FT-601-CN | E4: VF620J861LB007967 | F4: n/a | G4: Truck | H4: 19000 | I4: KG | J4: TG La Roche sur Yon (PF) | K4: =VLOOKUP(J4, correspondance!A:B, 2, FALSE) -> TG La Roche sur Yon (PF) | L4: 299910.7 | M4: 9088 | N4: n/a | O4: n/a | P4: n/a | Q4: n/a | R4: n/a | S4: n/a | T4: n/a | U4: Calibrated | V4: 14 avr. 2026 10:01 | W4: Boulevard de Port Gentil, Thouars, Nouvelle-Aquitaine, 79100 | X4: n/a | Y4: n/a | Z4: n/a | AA4: 0 | AB4: F SFR | AC4: true | AD4: n/a | AE4: CBL-VG-CHGV | AF4: n/a | AG4: Regulated
A5: GR-695-TJ | B5: VG54-EU | C5: GU3X-UGS-9YV | D5: n/a | E5: ZCFCP35A50D736039 | F5: n/a | J5: Site Bonneville | K5: =VLOOKUP(J5, correspondance!A:B, 2, FALSE) -> Site Bonneville | L5: 113342.3 | M5: 1930 | N5: n/a | O5: n/a | P5: n/a | Q5: n/a | R5: n/a | S5: n/a | T5: n/a | U5: Calibrated | V5: 14 avr. 2026 10:01 | W5: Route de Sallanches, Demi-Quartier, Auvergne-Rhône-Alpes, 74120 | X5: n/a | Y5: n/a | Z5: n/a | AA5: 0 | AB5: F SFR | AC5: true | AD5: n/a | AE5: CBL-VG-COBDII-Y0 | AF5: n/a | AG5: Regulated
A6: GM-743-ST | B6: VG54-EU | C6: GR58-DA4-PVN | D6: GM-743-ST | E6: VF640J565NB019779 | F6: n/a | G6: Truck | H6: 10000 | I6: KG | J6: TG IDF VALENTON | K6: =VLOOKUP(J6, correspondance!A:B, 2, FALSE) -> TG IDF VALENTON | L6: 70386.9 | M6: 3442 | N6: n/a | O6: n/a | P6: n/a | Q6: n/a | R6: n/a | S6: n/a | T6: n/a | U6: Calibrated | V6: 14 avr. 2026 10:01 | W6: Rue de Schomberg, Paris, Île-de-France, 75004 | X6: n/a | Y6: n/a | Z6: n/a | AA6: 0 | AB6: F SFR | AC6: true | AD6: n/a | AE6: CBL-VG-CHGV | AF6: n/a | AG6: Regulated
A7: GM-757-SV | B7: VG54-EU | C7: GWKS-B4Z-AV2 | D7: GM-757-SV | E7: VF620J961NB000566 | F7: n/a | G7: Truck | H7: 16776 | I7: KG | J7: TG IDF VALENTON | K7: =VLOOKUP(J7, correspondance!A:B, 2, FALSE) -> TG IDF VALENTON | L7: 30947.7 | M7: 2396 | N7: n/a | O7: n/a | P7: n/a | Q7: n/a | R7: n/a | S7: n/a | T7: n/a | U7: Calibrated | V7: 14 avr. 2026 10:01 | W7: 14 Rue Ferme de la Tour, Valenton, Île-de-France, 94460 | X7: n/a | Y7: n/a | Z7: n/a | AA7: 0 | AB7: F SFR | AC7: true | AD7: n/a | AE7: CBL-VG-CHGV | AF7: n/a | AG7: Regulated
A8: FT-966-XF | B8: VG54-EU | C8: GECZ-HHA-E3F | D8: FT-966-XF | E8: VF620J861LB008231 | F8: n/a | G8: Truck | H8: 16000 | I8: KG | J8: TG IDF VALENTON | K8: =VLOOKUP(J8, correspondance!A:B, 2, FALSE) -> TG IDF VALENTON | L8: 167192.0 | M8: 11883 | N8: n/a | O8: n/a | P8: n/a | Q8: n/a | R8: n/a | S8: n/a | T8: n/a | U8: Calibrated | V8: 14 avr. 2026 10:01 | W8: 14 Rue Ferme de la Tour, Valenton, Île-de-France, 94460 | X8: n/a | Y8: n/a | Z8: n/a | AA8: 0 | AB8: F SFR | AC8: true | AD8: n/a | AE8: CBL-VG-CHGV | AF8: n/a | AG8: Regulated
A9: EJ-847-PS | B9: VG54-EU | C9: GZAK-5WG-488 | D9: EJ-847-PS | E9: ZCFCD35A40D578513 | F9: n/a | G9: Truck | H9: 3500 | I9: KG | J9: TG IDF VALENTON | K9: =VLOOKUP(J9, correspondance!A:B, 2, FALSE) -> TG IDF VALENTON | L9: 366128.4 | M9: 7298 | N9: n/a | O9: n/a | P9: n/a | Q9: n/a | R9: n/a | S9: n/a | T9: n/a | U9: Calibrated | V9: 14 avr. 2026 10:01 | W9: Boulevard Périphérique Extérieur, Paris, Île-de-France, 75014 | X9: n/a | Y9: n/a | Z9: n/a | AA9: 0 | AB9: F SFR | AC9: true | AD9: n/a | AE9: CBL-VG-COBDII-Y0 | AF9: n/a | AG9: Regulated
A10: EA-206-DW | B10: VG54-EU | C10: GDSE-UXJ-C7X | D10: EA-206-DW | E10: VF640J562GB003610 | F10: n/a | G10: Truck | H10: 16000 | I10: KG | J10: TG Rennes (PF) | K10: =VLOOKUP(J10, correspondance!A:B, 2, FALSE) -> TG Rennes (PF) | L10: 388728.9 | M10: 8304 | N10: n/a | O10: n/a | P10: n/a | Q10: n/a | R10: n/a | S10: n/a | T10: n/a | U10: Calibrated | V10: 14 avr. 2026 10:01 | W10: Caulnes, Bretagne, 22350 | X10: n/a | Y10: n/a | Z10: n/a | AA10: 0 | AB10: F SFR | AC10: true | AD10: n/a | AE10: CBL-VG-CHGV | AF10: n/a | AG10: Regulated
A11: FC-613-XX | B11: VG54-EU | C11: GMK3-VUC-3E4 | D11: FC-613-XX | E11: VF620J860KB005786 | F11: n/a | G11: Truck | H11: 16000 | I11: KG | J11: TG Ouest | K11: =VLOOKUP(J11, correspondance!A:B, 2, FALSE) -> TG Ouest | L11: 334087.3 | M11: 10688 | N11: n/a | O11: n/a | P11: n/a | Q11: n/a | R11: n/a | S11: n/a | T11: n/a | U11: Calibrated | V11: 14 avr. 2026 10:01 | W11: 13 Promenade du Bout du Monde, Angers, Pays de la Loire, 49100 | X11: n/a | Y11: n/a | Z11: n/a | AA11: 0 | AB11: F SFR | AC11: true | AD11: n/a | AE11: CBL-VG-CHGV | AF11: n/a | AG11: Regulated
A12: GH-033-QX | B12: VG54-EU | C12: GYFP-PJJ-FJF | D12: GH-033-QX | E12: VF611A367ND038308 | F12: n/a | G12: Truck | H12: 19000 | I12: KG | J12: TG Ouest | K12: =VLOOKUP(J12, correspondance!A:B, 2, FALSE) -> TG Ouest | L12: 278333.1 | M12: 3912 | N12: n/a | O12: n/a | P12: n/a | Q12: n/a | R12: n/a | S12: n/a | T12: n/a | U12: Calibrated | V12: 14 avr. 2026 10:01 | W12: Rue Véga, Carquefou, Pays de la Loire, 44470 | X12: n/a | Y12: n/a | Z12: n/a | AA12: 0 | AB12: F SFR | AC12: true | AD12: n/a | AE12: CBL-VG-CHGV | AF12: n/a | AG12: Regulated
A13: FA-902-XZ | B13: VG54-EU | C13: GMCU-T8J-A9U | D13: FA-902-XZ | E13: XLRAEL2700L475280 | F13: n/a | G13: Truck | H13: 15500 | I13: KG | J13: TG Ouest | K13: =VLOOKUP(J13, correspondance!A:B, 2, FALSE) -> TG Ouest | L13: 375445.3 | M13: 9461 | N13: n/a | O13: n/a | P13: n/a | Q13: n/a | R13: n/a | S13: n/a | T13: n/a | U13: Calibrated | V13: 14 avr. 2026 10:01 | W13: Angers, Pays de la Loire, 49035 | X13: n/a | Y13: n/a | Z13: n/a | AA13: 0 | AB13: F SFR | AC13: true | AD13: n/a | AE13: CBL-VG-CFMS | AF13: n/a | AG13: Regulated
A14: GH-931-QW | B14: VG54-EU | C14: GYHU-FUP-SY9 | D14: GH-931-QW | E14: VF611A365ND038307 | F14: n/a | G14: Truck | H14: 19000 | I14: KG | J14: TG Ouest | K14: =VLOOKUP(J14, correspondance!A:B, 2, FALSE) -> TG Ouest | L14: 283091.8 | M14: 4238 | N14: n/a | O14: n/a | P14: n/a | Q14: n/a | R14: n/a | S14: n/a | T14: n/a | U14: Calibrated | V14: 14 avr. 2026 10:01 | W14: Rue Véga, Carquefou, Pays de la Loire, 44470 | X14: n/a | Y14: n/a | Z14: n/a | AA14: 0 | AB14: F SFR | AC14: true | AD14: n/a | AE14: CBL-VG-CHGV | AF14: n/a | AG14: Regulated
A15: ER-911-TW | B15: VG54-EU | C15: GGWD-5M4-6UZ | D15: ER-911-TW | E15: VF640J566HB007659 | F15: n/a | G15: Truck | H15: 16000 | I15: KG | J15: TG Rennes (PF) | K15: =VLOOKUP(J15, correspondance!A:B, 2, FALSE) -> TG Rennes (PF) | L15: 395812.3 | M15: 8684 | N15: n/a | O15: n/a | P15: n/a | Q15: n/a | R15: n/a | S15: n/a | T15: n/a | U15: Calibrated | V15: 14 avr. 2026 10:01 | W15: 13ter Place des Lices, Rennes, Bretagne, 35000 | X15: n/a | Y15: n/a | Z15: n/a | AA15: 0 | AB15: F SFR | AC15: true | AD15: n/a | AE15: CBL-VG-CHGV | AF15: n/a | AG15: Regulated
A16: DX-992-LX | B16: VG54-EU | C16: GA6Y-ACC-ZGN | D16: DX-992-LX | E16: YV2T0X1A2FZ103749 | F16: n/a | G16: Truck | H16: 16000 | I16: KG | J16: TG St Brieuc (PF) | K16: =VLOOKUP(J16, correspondance!A:B, 2, FALSE) -> TG St Brieuc (PF) | L16: 482584.4 | M16: 10496 | N16: n/a | O16: n/a | P16: n/a | Q16: n/a | R16: n/a | S16: n/a | T16: n/a | U16: Calibrated | V16: 14 avr. 2026 10:01 | W16: N 24, Ploërmel, Bretagne, 56800 | X16: n/a | Y16: n/a | Z16: n/a | AA16: 0 | AB16: F SFR | AC16: true | AD16: n/a | AE16: CBL-VG-CHGV | AF16: n/a | AG16: Regulated
A17: GS-381-DM | B17: VG54-EU | C17: GVEY-USU-EYR | D17: GS-381-DM | E17: VF620J868PB012198 | F17: n/a | G17: Truck | H17: 19000 | I17: KG | J17: B100, TG Ouest | K17: =VLOOKUP(J17, correspondance!A:B, 2, FALSE) -> TG Ouest | L17: 126868.6 | M17: 3207 | N17: n/a | O17: n/a | P17: n/a | Q17: n/a | R17: n/a | S17: n/a | T17: n/a | U17: Calibrated | V17: 14 avr. 2026 10:01 | W17: 11 Rue Lieutenant-Colonel Dubois, Vezin-le-Coquet, Bretagne, 35132 | X17: n/a | Y17: n/a | Z17: n/a | AA17: 0 | AB17: F SFR | AC17: true | AD17: n/a | AE17: CBL-VG-CHGV | AF17: n/a | AG17: Regulated
... A119: HB-986-WN | B119: VG54-EU | C119: GNK2-PDC-NCY | D119: HB-986-WN | E119: VF611A362SD055870 | F119: n/a | G119: Truck | H119: 44000 | I119: KG | J119: TG CENTRE EST | K119: =VLOOKUP(J119, correspondance!A:B, 2, FALSE) -> TG CENTRE EST | L119: 125145.7 | M119: 2033 | N119: n/a | O119: n/a | P119: n/a | Q119: n/a | R119: n/a | S119: n/a | T119: n/a | U119: Calibrated | V119: 14 avr. 2026 10:01 | W119: Chemin des Petits Rocs, Avermes, Auvergne-Rhône-Alpes, 03000 | X119: n/a | Y119: n/a | Z119: n/a | AA119: 0 | AB119: F SFR | AC119: true | AD119: n/a | AE119: CBL-VG-CHGV | AF119: n/a | AG119: Regulated
A120: DW-586-QW | B120: VG54-EU | C120: GGB2-M5J-SJH | D120: DW-586-QW | E120: VF620J866TB016048 | F120: n/a | G120: Truck | H120: 19000 | I120: KG | J120: TG CENTRE EST | K120: =VLOOKUP(J120, correspondance!A:B, 2, FALSE) -> TG CENTRE EST | L120: 1411.9 | M120: 27 | N120: n/a | O120: n/a | P120: n/a | Q120: n/a | R120: n/a | S120: n/a | T120: n/a | U120: Calibrated | V120: 14 avr. 2026 10:01 | W120: 2 Place des Roches, Lormes, Bourgogne-Franche-Comté, 58140 | X120: n/a | Y120: n/a | Z120: n/a | AA120: 0 | AB120: F SFR | AC120: true | AD120: n/a | AF120: n/a | AG120: Regulated
A121: FQ-744-SP | B121: VG54-EU | C121: GC8K-U9P-GU7 | D121: FQ-744-SP | E121: VF611A364LD025478 | F121: n/a | G121: Truck | H121: 40000 | I121: KG | J121: TG CENTRE EST | K121: =VLOOKUP(J121, correspondance!A:B, 2, FALSE) -> TG CENTRE EST | L121: 675957.9 | M121: 10954 | N121: n/a | O121: n/a | P121: n/a | Q121: n/a | R121: n/a | S121: n/a | T121: n/a | U121: Calibrated | V121: 14 avr. 2026 10:01 | W121: Rue Jacques Cœur, Yzeure, Auvergne-Rhône-Alpes, 03400 | X121: n/a | Y121: n/a | Z121: n/a | AA121: 0 | AB121: F SFR | AC121: true | AD121: n/a | AE121: CBL-VG-CHGV | AF121: n/a | AG121: Regulated
A122: GR-695-TJ | B122: VG54-EU | C122: GN93-7NK-JKH | D122: GR-695-TJ | E122: ZCFCP35A50D736039 | F122: n/a | G122: Truck | H122: 3500 | I122: KG | J122: Site Bonneville | K122: =VLOOKUP(J122, correspondance!A:B, 2, FALSE) -> Site Bonneville | L122: 113342.3 | M122: 1930 | N122: n/a | O122: n/a | P122: n/a | Q122: n/a | R122: n/a | S122: n/a | T122: n/a | U122: Calibrated | V122: 14 avr. 2026 10:01 | W122: Route de Sallanches, Demi-Quartier, Auvergne-Rhône-Alpes, 74120 | X122: n/a | Y122: n/a | Z122: n/a | AA122: 0 | AB122: F SFR | AC122: true | AD122: n/a | AE122: CBL-VG-COBDII-Y0 | AF122: n/a | AG122: Regulated
A123: DR-208-FB | B123: VG54-EU | C123: G5AT-K89-5RA | D123: DR-208-FB | E123: VF620J864FB000788 | F123: n/a | G123: Truck | H123: 19000 | I123: KG | J123: TG CENTRE EST | K123: =VLOOKUP(J123, correspondance!A:B, 2, FALSE) -> TG CENTRE EST | L123: 716557.0 | M123: 13595 | N123: n/a | O123: n/a | P123: n/a | Q123: n/a | R123: n/a | S123: n/a | T123: n/a | U123: Calibrated | V123: 10 avr. 2026 17:15 | W123: D 707, Avermes, Auvergne-Rhône-Alpes, 03000 | X123: n/a | Y123: n/a | Z123: n/a | AA123: 0 | AB123: F SFR | AC123: true | AD123: n/a | AE123: CBL-VG-CFMS | AF123: n/a | AG123: Regulated
A124: EQ-533-MQ | B124: VG54-EU | C124: GYGM-VD2-X5E | D124: EQ-533-MQ | E124: VF611A368TD062596 | F124: n/a | G124: Truck | H124: 19000 | I124: KG | J124: TG CENTRE EST | K124: =VLOOKUP(J124, correspondance!A:B, 2, FALSE) -> TG CENTRE EST | L124: 1243.3 | M124: 22 | N124: n/a | O124: n/a | P124: n/a | Q124: n/a | R124: n/a | S124: n/a | T124: n/a | U124: Calibrated | V124: 14 avr. 2026 10:01 | W124: D 951, Saint-Aignan-des-Noyers, Centre-Val de Loire, 18600 | X124: n/a | Y124: n/a | Z124: n/a | AA124: 0 | AB124: F SFR | AC124: true | AD124: n/a | AE124: CBL-VG-CHGV | AF124: n/a | AG124: Regulated
A125: GY-968-QC | B125: VG54-EU | C125: G3R5-YDE-7UN | D125: GY-968-QC | E125: VF620J867RB012938 | F125: n/a | G125: Truck | H125: 16000 | I125: KG | J125: TG CENTRE EST | K125: =VLOOKUP(J125, correspondance!A:B, 2, FALSE) -> TG CENTRE EST | L125: 117692.1 | M125: 2290 | N125: n/a | O125: n/a | P125: n/a | Q125: n/a | R125: n/a | S125: n/a | T125: n/a | U125: Calibrated | V125: 14 avr. 2026 10:01 | W125: Avenue de Chazeuil, Varennes-sur-Allier, Auvergne-Rhône-Alpes, 03150 | X125: n/a | Y125: n/a | Z125: n/a | AA125: 0 | AB125: F SFR | AC125: true | AD125: n/a | AE125: CBL-VG-CHGV | AF125: n/a | AG125: Regulated
A126: DW-935-QW | B126: VG54-EU | C126: G5KU-FZC-EEC | D126: DW-935-QW | E126: VF620J868TB016049 | F126: n/a | G126: Truck | H126: 19000 | I126: KG | J126: TG CENTRE EST | K126: =VLOOKUP(J126, correspondance!A:B, 2, FALSE) -> TG CENTRE EST | L126: 2810.4 | M126: 55 | N126: n/a | O126: n/a | P126: n/a | Q126: n/a | R126: n/a | S126: n/a | T126: n/a | U126: Calibrated | V126: 14 avr. 2026 10:01 | W126: Rue du Courtioux, Marcillat-en-Combraille, Auvergne-Rhône-Alpes, 03420 | X126: n/a | Y126: n/a | Z126: n/a | AA126: 0 | AB126: F SFR | AC126: true | AD126: n/a | AE126: CBL-VG-CHGV | AF126: n/a | AG126: Regulated
A127: CC-024-RY | B127: VG54-EU | C127: GPR4-BUW-US5 | D127: CC-024-RY | E127: VF624GPA000057362 | F127: n/a | G127: Truck | H127: 19000 | I127: KG | J127: TG CENTRE OUEST | K127: =VLOOKUP(J127, correspondance!A:B, 2, FALSE) -> TG CENTRE OUEST | L127: 1457279.0 | M127: n/a | N127: n/a | O127: n/a | P127: n/a | Q127: n/a | R127: n/a | S127: n/a | T127: n/a | U127: Calibrated | V127: 14 avr. 2026 10:01 | W127: TRANSGOURMET CENTRE OUEST | X127: n/a | Y127: n/a | Z127: n/a | AA127: 0 | AB127: F SFR | AC127: true | AD127: n/a | AE127: CBL-VG-CHGV | AF127: n/a | AG127: Regulated
A128: GX-919-WX | B128: VG54-EU | C128: G8WH-GZ2-974 | D128: GX-919-WX | E128: VF620J164RB001647 | F128: n/a | G128: Truck | H128: 19000 | I128: KG | J128: TG CENTRE OUEST | K128: =VLOOKUP(J128, correspondance!A:B, 2, FALSE) -> TG CENTRE OUEST | L128: 162669.8 | M128: 2294 | N128: n/a | O128: n/a | P128: n/a | Q128: n/a | R128: n/a | S128: n/a | T128: n/a | U128: Calibrated | V128: 14 avr. 2026 10:01 | W128: TRANSGOURMET CENTRE OUEST | X128: n/a | Y128: n/a | Z128: n/a | AA128: 0 | AB128: F SFR | AC128: true | AD128: n/a | AE128: CBL-VG-CHGV | AF128: n/a | AG128: Regulated
A129: GR-794-YF | B129: VG54-EU | C129: GV3S-WZE-PGM | D129: GR-794-YF | E129: VF611A365RD046753 | F129: n/a | G129: Truck | H129: 19000 | I129: KG | J129: TG CENTRE OUEST | K129: =VLOOKUP(J129, correspondance!A:B, 2, FALSE) -> TG CENTRE OUEST | L129: 403807.3 | M129: 5948 | N129: n/a | O129: n/a | P129: n/a | Q129: n/a | R129: n/a | S129: n/a | T129: n/a | U129: Calibrated | V129: 14 avr. 2026 10:01 | W129: TRANSGOURMET CENTRE OUEST | X129: n/a | Y129: n/a | Z129: n/a | AA129: 0 | AB129: F SFR | AC129: true | AD129: n/a | AE129: CBL-VG-CHGV | AF129: n/a | AG129: Regulated
A130: HB-141-VX | B130: VG54-EU | C130: G9AU-FEG-352 | D130: HB-141-VX | E130: VF620J860SB014438 | F130: MICHALAK Michael | G130: Truck | H130: 19000 | I130: KG | J130: TG COULOMMIERS | K130: =VLOOKUP(J130, correspondance!A:B, 2, FALSE) -> TG COULOMMIERS | L130: 35491.7 | M130: 1500 | N130: n/a | O130: n/a | P130: n/a | Q130: n/a | R130: n/a | S130: n/a | T130: n/a | U130: Calibrated | V130: 14 avr. 2026 10:01 | W130: D 402, Beautheil-Saints, Île-de-France, 77120 | X130: n/a | Y130: n/a | Z130: n/a | AA130: 0 | AB130: F SFR | AC130: true | AD130: n/a | AE130: CBL-VG-CHGV | AF130: n/a | AG130: Regulated
A131: HB-491-NW | B131: VG54-EU | C131: GSFX-XMZ-C49 | D131: HB-491-NW | E131: VF620J860SB014410 | F131: n/a | G131: Truck | H131: 19000 | I131: KG | J131: TG COULOMMIERS | K131: =VLOOKUP(J131, correspondance!A:B, 2, FALSE) -> TG COULOMMIERS | L131: 51783.5 | M131: 2145 | N131: n/a | O131: n/a | P131: n/a | Q131: n/a | R131: n/a | S131: n/a | T131: n/a | U131: Calibrated | V131: 14 avr. 2026 10:01 | W131: Rue du Jariel, Coulommiers, Île-de-France, 77120 | X131: n/a | Y131: n/a | Z131: n/a | AA131: 0 | AB131: F SFR | AC131: true | AD131: n/a | AE131: CBL-VG-CHGV | AF131: n/a | AG131: Regulated
A132: DX-989-DN | B132: VG54-EU | C132: GRJR-CEU-MMF | D132: DX-989-DN | E132: VF620J862FB001390 | F132: n/a | G132: Truck | H132: 19000 | I132: KG | J132: TG COULOMMIERS | K132: =VLOOKUP(J132, correspondance!A:B, 2, FALSE) -> TG COULOMMIERS | L132: 507794.3 | M132: 12085 | N132: n/a | O132: n/a | P132: n/a | Q132: n/a | R132: n/a | S132: n/a | T132: n/a | U132: Calibrated | V132: 14 avr. 2026 10:01 | W132: D 402, Beautheil-Saints, Île-de-France, 77120 | X132: n/a | Y132: n/a | Z132: n/a | AA132: 0 | AB132: F SFR | AC132: true | AD132: n/a | AE132: CBL-VG-CHGV | AF132: n/a | AG132: Regulated
... A169: GP-949-BQ | B169: VG54-EU | C169: GBY2-STX-DPY | D169: GP-949-BQ | E169: VF620J861PB011359 | F169: n/a | G169: Truck | H169: 19000 | I169: KG | J169: Site Bonneville | K169: =VLOOKUP(J169, correspondance!A:B, 2, FALSE) -> Site Bonneville | L169: 165885.6 | M169: 4339 | N169: n/a | O169: n/a | P169: n/a | Q169: n/a | R169: n/a | S169: n/a | T169: n/a | U169: Calibrated | V169: 14 avr. 2026 10:01 | W169: Centre Commercial le Warrens, Sallanches, Auvergne-Rhône-Alpes, 74700 | X169: n/a | Y169: n/a | Z169: n/a | AA169: 0 | AB169: F SFR | AC169: true | AD169: n/a | AE169: CBL-VG-CHGV | AF169: n/a | AG169: Regulated
A170: GT-494-NY | B170: VG55-EU | C170: GGMF-GRK-ZUG | D170: GT-494-NY | E170: VF1VAE00070169427 | F170: n/a | G170: Truck | J170: TGFL-DELTA LOGISTIQUE | K170: =VLOOKUP(J170, correspondance!A:B, 2, FALSE) -> TGFL-DELTA LOGISTIQUE | L170: 486.0 | M170: n/a | N170: n/a | O170: n/a | P170: n/a | Q170: n/a | R170: n/a | S170: n/a | T170: n/a | U170: Calibrated | V170: 14 avr. 2026 10:01 | W170: Avenue Charles Lindbergh, Rungis, Île-de-France, 94150 | X170: n/a | Y170: n/a | Z170: n/a | AA170: 0 | AB170: Orange F | AC170: true | AD170: n/a | AE170: CBL-VG-COBDII-Y0 | AF170: n/a | AG170: Regulated
A171: GN-240-VQ | B171: VG55-EU | C171: GFPW-3PW-5YA | D171: GN-240-VQ | E171: VF1VAE00070169427 | F171: n/a | G171: Truck | J171: TGFL-DELTA LOGISTIQUE | K171: =VLOOKUP(J171, correspondance!A:B, 2, FALSE) -> TGFL-DELTA LOGISTIQUE | L171: 31601.0 | M171: n/a | N171: n/a | O171: n/a | P171: n/a | Q171: n/a | R171: n/a | S171: n/a | T171: n/a | U171: Calibrated | V171: 14 avr. 2026 10:01 | W171: 21 Avenue d'Auvergne, Chevilly-Larue, Île-de-France, 94550 | X171: n/a | Y171: n/a | Z171: n/a | AA171: 0 | AB171: Orange F | AC171: true | AD171: n/a | AE171: CBL-VG-COBDII-Y0 | AF171: n/a | AG171: Regulated
A172: Boitier téléchargement tachys CARQUEFOU | B172: VG54-EU | C172: GR2A-VPG-46X | D172: Z boitier téléchgt | F172: n/a | G172: Automatic | J172: TG OUEST | K172: =VLOOKUP(J172, correspondance!A:B, 2, FALSE) -> TG Ouest | L172: n/a | M172: n/a | N172: n/a | O172: n/a | P172: n/a | Q172: n/a | R172: n/a | S172: n/a | T172: n/a | U172: Not Calibrated | V172: 14 avr. 2026 10:01 | W172: Avenue Syrma, Carquefou, Pays de la Loire, 44470 | X172: n/a | Y172: n/a | Z172: n/a | AA172: 0 | AB172: F SFR | AC172: true | AD172: n/a | AE172: CBL-VG-CPWR | AF172: n/a | AG172: Regulated
A173: GG9S-4BS-FN4 | B173: VG54-EU | C173: GG9S-4BS-FN4 | D173: n/a | F173: n/a | K173: =VLOOKUP(J173, correspondance!A:B, 2, FALSE) -> #N/A | L173: n/a | M173: n/a | N173: n/a | O173: n/a | P173: n/a | Q173: n/a | R173: n/a | S173: n/a | T173: n/a | U173: Not Calibrated | V173: n/a | W173: Location unknown | X173: n/a | Y173: n/a | Z173: n/a | AA173: 0 | AB173: n/a | AC173: n/a | AD173: n/a | AF173: n/a | AG173: Regulated
A174: GUSX-HV8-ZMT | B174: VG54-EU | C174: GUSX-HV8-ZMT | D174: n/a | F174: n/a | K174: =VLOOKUP(J174, correspondance!A:B, 2, FALSE) -> #N/A | L174: n/a | M174: n/a | N174: n/a | O174: n/a | P174: n/a | Q174: n/a | R174: n/a | S174: n/a | T174: n/a | U174: Not Calibrated | V174: n/a | W174: Location unknown | X174: n/a | Y174: n/a | Z174: n/a | AA174: 0 | AB174: n/a | AC174: n/a | AD174: n/a | AF174: n/a | AG174: Regulated
A175: G2WW-KVA-NYS | B175: VG54-EU | C175: G2WW-KVA-NYS | D175: n/a | F175: n/a | K175: =VLOOKUP(J175, correspondance!A:B, 2, FALSE) -> #N/A | L175: n/a | M175: n/a | N175: n/a | O175: n/a | P175: n/a | Q175: n/a | R175: n/a | S175: n/a | T175: n/a | U175: Not Calibrated | V175: n/a | W175: Location unknown | X175: n/a | Y175: n/a | Z175: n/a | AA175: 0 | AB175: n/a | AC175: n/a | AD175: n/a | AF175: n/a | AG175: Regulated
A176: G2KH-3SN-YVA | B176: VG54-EU | C176: G2KH-3SN-YVA | D176: n/a | F176: n/a | K176: =VLOOKUP(J176, correspondance!A:B, 2, FALSE) -> #N/A | L176: n/a | M176: n/a | N176: n/a | O176: n/a | P176: n/a | Q176: n/a | R176: n/a | S176: n/a | T176: n/a | U176: Not Calibrated | V176: n/a | W176: Location unknown | X176: n/a | Y176: n/a | Z176: n/a | AA176: 0 | AB176: n/a | AC176: n/a | AD176: n/a | AF176: n/a | AG176: Regulated
A177: G4XR-8ZH-KV9 | B177: VG54-EU | C177: G4XR-8ZH-KV9 | D177: n/a | F177: n/a | K177: =VLOOKUP(J177, correspondance!A:B, 2, FALSE) -> #N/A | L177: n/a | M177: n/a | N177: n/a | O177: n/a | P177: n/a | Q177: n/a | R177: n/a | S177: n/a | T177: n/a | U177: Not Calibrated | V177: n/a | W177: Location unknown | X177: n/a | Y177: n/a | Z177: n/a | AA177: 0 | AB177: n/a | AC177: n/a | AD177: n/a | AF177: n/a | AG177: Regulated
...

Sheet correspondance
A1: tag | B1: site
A2: TG CENTRE EST | B2: TG CENTRE EST
A3: TG La Roche sur Yon (PF) | B3: TG La Roche sur Yon (PF)
A4: Site Bonneville | B4: Site Bonneville
A5: TG IDF VALENTON | B5: TG IDF VALENTON
A6: TG Rennes (PF) | B6: TG Rennes (PF)
A7: TG Ouest | B7: TG Ouest
A8: TG St Brieuc (PF) | B8: TG St Brieuc (PF)
A9: B100, TG Ouest | B9: TG Ouest
A10: TG Caen (PF) | B10: TG Caen (PF)
A11: TG Laval (PF) | B11: TG Laval (PF)
A12: TG Quimper (PF) | B12: TG Quimper (PF)
... A53: TG IDF - Valenton, TG IDF VALENTON | B53: TG IDF VALENTON

Sheet Commandes
A1: Commandes de boitiers 2024-2026
A3: Date | B3: Numéro de commande | C3: Type de produit | D3: Boitier ID | E3: Quantité | F3: Immatriculation | G3: Transgourmet
A4: 45320 | B4: S-1477736 | C4: HW-VG54-EU | D4: G2VD-P2R-XFY | E4: 1 | F4: =IFERROR(IF(LEN(_xlfn.XLOOKUP(D4, 'Parc Samsara'!B:B, 'Parc Samsara'!A:A)) >9, "Non équipé", _xlfn.XLOOKUP(D4, 'Parc Samsara'!B:B, 'Parc Samsara'!A:A)), "Non équipé") -> GF-361-NP | G4: oui
A5: 45320 | B5: S-1477736 | C5: HW-VG54-EU | D5: G96Z-EEG-4MH | E5: 1 | F5: =IFERROR(IF(LEN(_xlfn.XLOOKUP(D5, 'Parc Samsara'!B:B, 'Parc Samsara'!A:A)) >9, "Non équipé", _xlfn.XLOOKUP(D5, 'Parc Samsara'!B:B, 'Parc Samsara'!A:A)), "Non équipé") -> Non équipé | G5: oui
A6: 45320 | B6: S-1477736 | C6: HW-VG54-EU | D6: GEEC-3FB-ZNB | E6: 1 | F6: =IFERROR(IF(LEN(_xlfn.XLOOKUP(D6, 'Parc Samsara'!B:B, 'Parc Samsara'!A:A)) >9, "Non équipé", _xlfn.XLOOKUP(D6, 'Parc Samsara'!B:B, 'Parc Samsara'!A:A)), "Non équipé") -> Non équipé | G6: oui
A7: 45320 | B7: S-1477736 | C7: HW-VG54-EU | D7: GG42-MAR-WA6 | E7: 1 | F7: =IFERROR(IF(LEN(_xlfn.XLOOKUP(D7, 'Parc Samsara'!B:B, 'Parc Samsara'!A:A)) >9, "Non équipé", _xlfn.XLOOKUP(D7, 'Parc Samsara'!B:B, 'Parc Samsara'!A:A)), "Non équipé") -> GL-123-JV | G7: oui
A8: 45320 | B8: S-1477736 | C8: HW-VG54-EU | D8: G4NR-YWZ-KJG | E8: 1 | F8: =IFERROR(IF(LEN(_xlfn.XLOOKUP(D8, 'Parc Samsara'!B:B, 'Parc Samsara'!A:A)) >9, "Non équipé", _xlfn.XLOOKUP(D8, 'Parc Samsara'!B:B, 'Parc Samsara'!A:A)), "Non équipé") -> EZ-274-HC | G8: oui
A9: 45320 | B9: S-1477736 | C9: HW-VG54-EU | D9: GN9P-NBY-M3M | E9: 1 | F9: =IFERROR(IF(LEN(_xlfn.XLOOKUP(D9, 'Parc Samsara'!B:B, 'Parc Samsara'!A:A)) >9, "Non équipé", _xlfn.XLOOKUP(D9, 'Parc Samsara'!B:B, 'Parc Samsara'!A:A)), "Non équipé") -> FT-699-DD | G9: oui
A10: 45320 | B10: S-1477736 | C10: HW-VG54-EU | D10: G6RF-DT5-DMX | E10: 1 | F10: =IFERROR(IF(LEN(_xlfn.XLOOKUP(D10, 'Parc Samsara'!B:B, 'Parc Samsara'!A:A)) >9, "Non équipé", _xlfn.XLOOKUP(D10, 'Parc Samsara'!B:B, 'Parc Samsara'!A:A)), "Non équipé") -> GX-465-SM | G10: oui
A11: 45320 | B11: S-1477736 | C11: HW-VG54-EU | D11: GXGX-5CR-4SX | E11: 1 | F11: =IFERROR(IF(LEN(_xlfn.XLOOKUP(D11, 'Parc Samsara'!B:B, 'Parc Samsara'!A:A)) >9, "Non équipé", _xlfn.XLOOKUP(D11, 'Parc Samsara'!B:B, 'Parc Samsara'!A:A)), "Non équipé") -> EA-702-LC | G11: oui | J11: NB boitiers commandé : | K11: =SUM(E:E) -> 880
A12: 45320 | B12: S-1477736 | C12: HW-VG54-EU | D12: GNZX-TPN-H3F | E12: 1 | F12: =IFERROR(IF(LEN(_xlfn.XLOOKUP(D12, 'Parc Samsara'!B:B, 'Parc Samsara'!A:A)) >9, "Non équipé", _xlfn.XLOOKUP(D12, 'Parc Samsara'!B:B, 'Parc Samsara'!A:A)), "Non équipé") -> FA-734-DL | G12: oui
A13: 45320 | B13: S-1477736 | C13: HW-VG54-EU | D13: GW4B-G4D-EX7 | E13: 1 | F13: =IFERROR(IF(LEN(_xlfn.XLOOKUP(D13, 'Parc Samsara'!B:B, 'Parc Samsara'!A:A)) >9, "Non équipé", _xlfn.XLOOKUP(D13, 'Parc Samsara'!B:B, 'Parc Samsara'!A:A)), "Non équipé") -> HJ-008-RZ | G13: oui
A14: 45320 | B14: S-1477736 | C14: HW-VG54-EU | D14: GWXD-959-9N9 | E14: 1 | F14: =IFERROR(IF(LEN(_xlfn.XLOOKUP(D14, 'Parc Samsara'!B:B, 'Parc Samsara'!A:A)) >9, "Non équipé", _xlfn.XLOOKUP(D14, 'Parc Samsara'!B:B, 'Parc Samsara'!A:A)), "Non équipé") -> FZ-659-XT | G14: oui | I14: Nombre de boitiers commandé non utilisé | L14: Nombre de boitiers par site
A15: 45320 | B15: S-1477736 | C15: HW-VG54-EU | D15: GKWD-W8V-RDZ | E15: 1 | F15: =IFERROR(IF(LEN(_xlfn.XLOOKUP(D15, 'Parc Samsara'!B:B, 'Parc Samsara'!A:A)) >9, "Non équipé", _xlfn.XLOOKUP(D15, 'Parc Samsara'!B:B, 'Parc Samsara'!A:A)), "Non équipé") -> GK-960-SQ | G15: oui
A16: 45320 | B16: S-1477736 | C16: HW-VG54-EU | D16: GA9K-7CZ-VR8 | E16: 1 | F16: =IFERROR(IF(LEN(_xlfn.XLOOKUP(D16, 'Parc Samsara'!B:B, 'Parc Samsara'!A:A)) >9, "Non équipé", _xlfn.XLOOKUP(D16, 'Parc Samsara'!B:B, 'Parc Samsara'!A:A)), "Non équipé") -> GJ-484-DE | G16: oui
A17: 45320 | B17: S-1477736 | C17: HW-VG54-EU | D17: GKRC-UKC-63Y | E17: 1 | F17: =IFERROR(IF(LEN(_xlfn.XLOOKUP(D17, 'Parc Samsara'!B:B, 'Parc Samsara'!A:A)) >9, "Non équipé", _xlfn.XLOOKUP(D17, 'Parc Samsara'!B:B, 'Parc Samsara'!A:A)), "Non équipé") -> ED-972-WP | G17: oui | I17: Immatriculation | J17: (Plusieurs éléments) | L17: Site | M17: Nombre de Boitier
A18: 45320 | B18: S-1477736 | C18: HW-VG54-EU | D18: G6FA-F93-M9Y | E18: 1 | F18: =IFERROR(IF(LEN(_xlfn.XLOOKUP(D18, 'Parc Samsara'!B:B, 'Parc Samsara'!A:A)) >9, "Non équipé", _xlfn.XLOOKUP(D18, 'Parc Samsara'!B:B, 'Parc Samsara'!A:A)), "Non équipé") -> FA-868-EE | G18: oui | L18: EUR Schiltigheim LIV | M18: 14
A19: 45320 | B19: S-1477736 | C19: HW-VG54-EU | D19: GAPW-56Z-T79 | E19: 1 | F19: =IFERROR(IF(LEN(_xlfn.XLOOKUP(D19, 'Parc Samsara'!B:B, 'Parc Samsara'!A:A)) >9, "Non équipé", _xlfn.XLOOKUP(D19, 'Parc Samsara'!B:B, 'Parc Samsara'!A:A)), "Non équipé") -> FA-720-DK | G19: oui | I19: Type de boitier | J19: Nombre de boitiers commandé non utilisé (samsara) | L19: PF Mouguerre | M19: 12
A20: 45320 | B20: S-1477736 | C20: HW-VG54-EU | D20: GGFJ-5G5-EB6 | E20: 1 | F20: =IFERROR(IF(LEN(_xlfn.XLOOKUP(D20, 'Parc Samsara'!B:B, 'Parc Samsara'!A:A)) >9, "Non équipé", _xlfn.XLOOKUP(D20, 'Parc Samsara'!B:B, 'Parc Samsara'!A:A)), "Non équipé") -> GZ-474-VB | G20: oui | I20: HW-VG54-EU | J20: 71 | L20: Site Bonneville | M20: 21
A21: 45320 | B21: S-1477736 | C21: HW-VG54-EU | D21: GKGS-96F-U57 | E21: 1 | F21: =IFERROR(IF(LEN(_xlfn.XLOOKUP(D21, 'Parc Samsara'!B:B, 'Parc Samsara'!A:A)) >9, "Non équipé", _xlfn.XLOOKUP(D21, 'Parc Samsara'!B:B, 'Parc Samsara'!A:A)), "Non équipé") -> ES-687-GK | G21: oui | I21: HW-VG55-EU | J21: 27 | L21: Site Laplace | M21: 8
A22: 45320 | B22: S-1477736 | C22: HW-VG54-EU | D22: GCK8-V2P-TDR | E22: 1 | F22: =IFERROR(IF(LEN(_xlfn.XLOOKUP(D22, 'Parc Samsara'!B:B, 'Parc Samsara'!A:A)) >9, "Non équipé", _xlfn.XLOOKUP(D22, 'Parc Samsara'!B:B, 'Parc Samsara'!A:A)), "Non équipé") -> GL-792-AC | G22: oui | I22: Total général | J22: 98 | L22: Site St Loubes | M22: 43
A23: 45320 | B23: S-1477736 | C23: HW-VG54-EU | D23: GGXT-5U5-HGJ | E23: 1 | F23: =IFERROR(IF(LEN(_xlfn.XLOOKUP(D23, 'Parc Samsara'!B:B, 'Parc Samsara'!A:A)) >9, "Non équipé", _xlfn.XLOOKUP(D23, 'Parc Samsara'!B:B, 'Parc Samsara'!A:A)), "Non équipé") -> GL-169-ZR | G23: oui | L23: TG ALPES | M23: 4
A24: 45320 | B24: S-1477736 | C24: HW-VG54-EU | D24: GT9V-PF5-224 | E24: 1 | F24: =IFERROR(IF(LEN(_xlfn.XLOOKUP(D24, 'Parc Samsara'!B:B, 'Parc Samsara'!A:A)) >9, "Non équipé", _xlfn.XLOOKUP(D24, 'Parc Samsara'!B:B, 'Parc Samsara'!A:A)), "Non équipé") -> HJ-710-ZK | G24: oui | L24: TG ALSACE | M24: 37
A25: 45320 | B25: S-1477736 | C25: HW-VG54-EU | D25: GRRX-9GK-W4S | E25: 1 | F25: =IFERROR(IF(LEN(_xlfn.XLOOKUP(D25, 'Parc Samsara'!B:B, 'Parc Samsara'!A:A)) >9, "Non équipé", _xlfn.XLOOKUP(D25, 'Parc Samsara'!B:B, 'Parc Samsara'!A:A)), "Non équipé") -> FT-906-HJ | G25: oui | L25: TG Arques | M25: 27
A26: 45320 | B26: S-1477736 | C26: HW-VG54-EU | D26: GSSH-F8T-KN5 | E26: 1 | F26: =IFERROR(IF(LEN(_xlfn.XLOOKUP(D26, 'Parc Samsara'!B:B, 'Parc Samsara'!A:A)) >9, "Non équipé", _xlfn.XLOOKUP(D26, 'Parc Samsara'!B:B, 'Parc Samsara'!A:A)), "Non équipé") -> GM-081-HH | G26: oui | L26: TG BOURGOGNE | M26: 25
A27: 45320 | B27: S-1477736 | C27: HW-VG54-EU | D27: G6XA-RSS-PXK | E27: 1 | F27: =IFERROR(IF(LEN(_xlfn.XLOOKUP(D27, 'Parc Samsara'!B:B, 'Parc Samsara'!A:A)) >9, "Non équipé", _xlfn.XLOOKUP(D27, 'Parc Samsara'!B:B, 'Parc Samsara'!A:A)), "Non équipé") -> GX-443-JW | G27: oui | L27: TG Caen (PF) | M27: 11
A28: 45320 | B28: S-1477736 | C28: HW-VG54-EU | D28: G9RZ-6H9-FDG | E28: 1 | F28: =IFERROR(IF(LEN(_xlfn.XLOOKUP(D28, 'Parc Samsara'!B:B, 'Parc Samsara'!A:A)) >9, "Non équipé", _xlfn.XLOOKUP(D28, 'Parc Samsara'!B:B, 'Parc Samsara'!A:A)), "Non équipé") -> GS-442-FA | G28: oui | L28: TG CENTRE EST | M28: 26
A29: 45320 | B29: S-1477736 | C29: HW-VG54-EU | D29: GFRH-J8Y-8WJ | E29: 1 | F29: =IFERROR(IF(LEN(_xlfn.XLOOKUP(D29, 'Parc Samsara'!B:B, 'Parc Samsara'!A:A)) >9, "Non équipé", _xlfn.XLOOKUP(D29, 'Parc Samsara'!B:B, 'Parc Samsara'!A:A)), "Non équipé") -> ES-754-HM | G29: oui | L29: TG CENTRE OUEST | M29: 52
A30: 45320 | B30: S-1477736 | C30: HW-VG54-EU | D30: GE3A-XXG-599 | E30: 1 | F30: =IFERROR(IF(LEN(_xlfn.XLOOKUP(D30, 'Parc Samsara'!B:B, 'Parc Samsara'!A:A)) >9, "Non équipé", _xlfn.XLOOKUP(D30, 'Parc Samsara'!B:B, 'Parc Samsara'!A:A)), "Non équipé") -> Non équipé | G30: oui | L30: TG COULOMMIERS | M30: 8
A31: 45320 | B31: S-1477736 | C31: HW-VG54-EU | D31: G3DW-XH2-YYC | E31: 1 | F31: =IFERROR(IF(LEN(_xlfn.XLOOKUP(D31, 'Parc Samsara'!B:B, 'Parc Samsara'!A:A)) >9, "Non équipé", _xlfn.XLOOKUP(D31, 'Parc Samsara'!B:B, 'Parc Samsara'!A:A)), "Non équipé") -> GX-430-GY | G31: oui | L31: TG Gouzeaucourt (PF) | M31: 8
A32: 45320 | B32: S-1477736 | C32: HW-VG54-EU | D32: GXJ5-RZT-MC2 | E32: 1 | F32: =IFERROR(IF(LEN(_xlfn.XLOOKUP(D32, 'Parc Samsara'!B:B, 'Parc Samsara'!A:A)) >9, "Non équipé", _xlfn.XLOOKUP(D32, 'Parc Samsara'!B:B, 'Parc Samsara'!A:A)), "Non équipé") -> GR-635-ZR | G32: oui | L32: TG IDF VALENTON | M32: 107
A33: 45320 | B33: S-1477736 | C33: HW-VG54-EU | D33: GMGG-A3M-CZ3 | E33: 1 | F33: =IFERROR(IF(LEN(_xlfn.XLOOKUP(D33, 'Parc Samsara'!B:B, 'Parc Samsara'!A:A)) >9, "Non équipé", _xlfn.XLOOKUP(D33, 'Parc Samsara'!B:B, 'Parc Samsara'!A:A)), "Non équipé") -> FA-585-FF | G33: oui | L33: TG IDF WISSOUS | M33: 13
A34: 45320 | B34: S-1477736 | C34: HW-VG54-EU | D34: GS92-G9U-XF2 | E34: 1 | F34: =IFERROR(IF(LEN(_xlfn.XLOOKUP(D34, 'Parc Samsara'!B:B, 'Parc Samsara'!A:A)) >9, "Non équipé", _xlfn.XLOOKUP(D34, 'Parc Samsara'!B:B, 'Parc Samsara'!A:A)), "Non équipé") -> GX-648-RZ | G34: oui | L34: TG La Roche sur Yon (PF) | M34: 5
... A55: 45320 | B55: S-1477736 | C55: HW-VG54-EU | D55: GRZY-PWF-BG9 | E55: 1 | F55: =IFERROR(IF(LEN(_xlfn.XLOOKUP(D55, 'Parc Samsara'!B:B, 'Parc Samsara'!A:A)) >9, "Non équipé", _xlfn.XLOOKUP(D55, 'Parc Samsara'!B:B, 'Parc Samsara'!A:A)), "Non équipé") -> HC-607-XV | G55: oui | L55: Total général | M55: 793
A56: 45320 | B56: S-1477736 | C56: HW-VG54-EU | D56: GPTR-HUR-PDP | E56: 1 | F56: =IFERROR(IF(LEN(_xlfn.XLOOKUP(D56, 'Parc Samsara'!B:B, 'Parc Samsara'!A:A)) >9, "Non équipé", _xlfn.XLOOKUP(D56, 'Parc Samsara'!B:B, 'Parc Samsara'!A:A)), "Non équipé") -> GR-232-ZS | G56: oui
A57: 45320 | B57: S-1477736 | C57: HW-VG54-EU | D57: GRRJ-HS2-UXY | E57: 1 | F57: =IFERROR(IF(LEN(_xlfn.XLOOKUP(D57, 'Parc Samsara'!B:B, 'Parc Samsara'!A:A)) >9, "Non équipé", _xlfn.XLOOKUP(D57, 'Parc Samsara'!B:B, 'Parc Samsara'!A:A)), "Non équipé") -> FA-205-EE | G57: oui
A58: 45320 | B58: S-1477736 | C58: HW-VG54-EU | D58: GHGD-PRE-VVM | E58: 1 | F58: =IFERROR(IF(LEN(_xlfn.XLOOKUP(D58, 'Parc Samsara'!B:B, 'Parc Samsara'!A:A)) >9, "Non équipé", _xlfn.XLOOKUP(D58, 'Parc Samsara'!B:B, 'Parc Samsara'!A:A)), "Non équipé") -> GZ-830-DZ | G58: oui
A59: 45320 | B59: S-1477736 | C59: HW-VG54-EU | D59: GWJF-W8B-XDU | E59: 1 | F59: =IFERROR(IF(LEN(_xlfn.XLOOKUP(D59, 'Parc Samsara'!B:B, 'Parc Samsara'!A:A)) >9, "Non équipé", _xlfn.XLOOKUP(D59, 'Parc Samsara'!B:B, 'Parc Samsara'!A:A)), "Non équipé") -> Non équipé | G59: oui
A60: 45320 | B60: S-1477736 | C60: HW-VG54-EU | D60: GT2U-5DX-3GS | E60: 1 | F60: =IFERROR(IF(LEN(_xlfn.XLOOKUP(D60, 'Parc Samsara'!B:B, 'Parc Samsara'!A:A)) >9, "Non équipé", _xlfn.XLOOKUP(D60, 'Parc Samsara'!B:B, 'Parc Samsara'!A:A)), "Non équipé") -> GL-643-QX | G60: oui
A61: 45320 | B61: S-1477736 | C61: HW-VG54-EU | D61: GXC6-M5Y-Z9V | E61: 1 | F61: =IFERROR(IF(LEN(_xlfn.XLOOKUP(D61, 'Parc Samsara'!B:B, 'Parc Samsara'!A:A)) >9, "Non équipé", _xlfn.XLOOKUP(D61, 'Parc Samsara'!B:B, 'Parc Samsara'!A:A)), "Non équipé") -> HA-887-GC | G61: oui
...

Sheet Parc Samsara
A1: Name | B1: Gateway Serial | C1: Location | D1: Last Connected | E1: Last Trip | F1: Status | G1: Current Fuel Level (%) | H1: Current Driver | I1: License Plate | J1: Tags | K1: Installed | L1: Make | M1: Model | N1: Year | O1: Vin | P1: Vehicle Type | Q1: présents | R1: Différents | S1: TRANSGOURMET
A2: EA-257-ZK | C2: Monnaie, Centre-Val de Loire, 37380 | D2: 11 oct. 2024 09:00 | E2: 11 oct. 2024 08:19 | F2: off | G2: 75 | I2: EA-257-ZK | J2: TG CENTRE OUEST | K2: true | L2: RENAULT | M2: D WIDE | N2: 2024 | O2: VF620J868RB013905 | P2: Automatic | Q2: =IFERROR(_xlfn.XLOOKUP(B2,'boitiers actifs'!C:C,'boitiers actifs'!A:A),"Pas installé") -> Pas installé | R2: =IF(Q2 = "Pas installé", "Pas installé", IF( Q2<>A2, "Différent du véhicule assigné", "Identique")) -> Pas installé | S2: =IF(B2 = "", "", VLOOKUP(B2, Commandes!D:G, 4, FALSE))
A3: CM-970-SV | C3: Sancerre, Centre-Val de Loire, 18300 | D3: 19 juin 2024 07:14 | E3: 19 juin 2024 06:33 | F3: off | G3: - | I3: CM-970-SV | J3: TG CENTRE EST | K3: true | L3: RENAULT | M3: MIDLUM | N3: 2012 | O3: VF644AGL000006703 | Q3: =IFERROR(_xlfn.XLOOKUP(B3,'boitiers actifs'!C:C,'boitiers actifs'!A:A),"Pas installé") -> Pas installé | R3: =IF(Q3 = "Pas installé", "Pas installé", IF( Q3<>A3, "Différent du véhicule assigné", "Identique")) -> Pas installé | S3: =IF(B3 = "", "", VLOOKUP(B3, Commandes!D:G, 4, FALSE))
A4: FR-281-MN | B4: GGMW-NMZ-NT6 | C4: La Roche-sur-Yon, Pays de la Loire, 85000 | D4: 14 avr. 2026 10:08 | E4: 13 avr. 2026 13:04 | F4: off | G4: 88 | I4: FR-281-MN | J4: TG La Roche sur Yon (PF) | K4: true | L4: RENAULT | M4: D WIDE | N4: 2020 | O4: VF620J86XLB007983 | P4: Truck | Q4: =IFERROR(_xlfn.XLOOKUP(B4,'boitiers actifs'!C:C,'boitiers actifs'!A:A),"Pas installé") -> FR-281-MN | R4: =IF(Q4 = "Pas installé", "Pas installé", IF( Q4<>A4, "Différent du véhicule assigné", "Identique")) -> Identique | S4: =IF(B4 = "", "", VLOOKUP(B4, Commandes!D:G, 4, FALSE)) -> #N/A
A5: FT-601-CN | B5: G4YX-EK6-Z7R | C5: Le Grand Cornet, Nouvelle-Aquitaine, 79330 | D5: 14 avr. 2026 10:08 | E5: On trip | F5: on | G5: 70 | H5: GUILLET Christian | I5: FT-601-CN | J5: TG La Roche sur Yon (PF) | K5: true | L5: RENAULT | M5: D WIDE | N5: 2020 | O5: VF620J861LB007967 | P5: Truck | Q5: =IFERROR(_xlfn.XLOOKUP(B5,'boitiers actifs'!C:C,'boitiers actifs'!A:A),"Pas installé") -> FT-601-CN | R5: =IF(Q5 = "Pas installé", "Pas installé", IF( Q5<>A5, "Différent du véhicule assigné", "Identique")) -> Identique | S5: =IF(B5 = "", "", VLOOKUP(B5, Commandes!D:G, 4, FALSE)) -> #N/A
A6: Boitier téléchargement tachys CARQUEFOU | B6: GR2A-VPG-46X | C6: Carquefou, Pays de la Loire, 44470 | D6: 14 avr. 2026 10:08 | F6: off | G6: - | I6: Z boitier téléchgt | J6: TG OUEST | K6: true | N6: 0 | P6: Automatic | Q6: =IFERROR(_xlfn.XLOOKUP(B6,'boitiers actifs'!C:C,'boitiers actifs'!A:A),"Pas installé") -> Boitier téléchargement tachys CARQUEFOU | R6: =IF(Q6 = "Pas installé", "Pas installé", IF( Q6<>A6, "Différent du véhicule assigné", "Identique")) -> Identique | S6: =IF(B6 = "", "", VLOOKUP(B6, Commandes!D:G, 4, FALSE)) -> #N/A
A7: GM-743-ST | B7: GR58-DA4-PVN | C7: Paris, Île-de-France, 75004 | D7: 14 avr. 2026 10:08 | E7: 14 avr. 2026 09:01 | F7: on | G7: 74 | H7: TRAORE SALLI | I7: GM-743-ST | J7: TG IDF VALENTON | K7: true | L7: RENAULT | M7: D | N7: 2022 | O7: VF640J565NB019779 | P7: Truck | Q7: =IFERROR(_xlfn.XLOOKUP(B7,'boitiers actifs'!C:C,'boitiers actifs'!A:A),"Pas installé") -> GM-743-ST | R7: =IF(Q7 = "Pas installé", "Pas installé", IF( Q7<>A7, "Différent du véhicule assigné", "Identique")) -> Identique | S7: =IF(B7 = "", "", VLOOKUP(B7, Commandes!D:G, 4, FALSE)) -> #N/A
A8: GM-757-SV | B8: GWKS-B4Z-AV2 | C8: Valenton, Île-de-France, 94460 | D8: 14 avr. 2026 10:08 | E8: 14 avr. 2026 10:02 | F8: idle | G8: 55 | H8: LEBERRE PATRICK | I8: GM-757-SV | J8: TG IDF VALENTON | K8: true | L8: RENAULT | M8: D WIDE | N8: 2022 | O8: VF620J961NB000566 | P8: Truck | Q8: =IFERROR(_xlfn.XLOOKUP(B8,'boitiers actifs'!C:C,'boitiers actifs'!A:A),"Pas installé") -> GM-757-SV | R8: =IF(Q8 = "Pas installé", "Pas installé", IF( Q8<>A8, "Différent du véhicule assigné", "Identique")) -> Identique | S8: =IF(B8 = "", "", VLOOKUP(B8, Commandes!D:G, 4, FALSE)) -> #N/A
A9: FT-966-XF | B9: GECZ-HHA-E3F | C9: Valenton, Île-de-France, 94460 | D9: 14 avr. 2026 10:08 | E9: 14 avr. 2026 09:23 | F9: off | G9: 69 | H9: KHAZRI Hamed | I9: FT-966-XF | J9: TG IDF VALENTON | K9: true | L9: RENAULT | M9: D WIDE | N9: 2020 | O9: VF620J861LB008231 | P9: Truck | Q9: =IFERROR(_xlfn.XLOOKUP(B9,'boitiers actifs'!C:C,'boitiers actifs'!A:A),"Pas installé") -> FT-966-XF | R9: =IF(Q9 = "Pas installé", "Pas installé", IF( Q9<>A9, "Différent du véhicule assigné", "Identique")) -> Identique | S9: =IF(B9 = "", "", VLOOKUP(B9, Commandes!D:G, 4, FALSE)) -> #N/A
A10: EJ-847-PS | B10: GZAK-5WG-488 | C10: Paris, Île-de-France, 75013 | D10: 14 avr. 2026 10:08 | E10: On trip | F10: on | G10: 48 | I10: EJ-847-PS | J10: TG IDF VALENTON | K10: true | L10: IVECO | M10: DAILY | N10: 2017 | O10: ZCFCD35A40D578513 | P10: Truck | Q10: =IFERROR(_xlfn.XLOOKUP(B10,'boitiers actifs'!C:C,'boitiers actifs'!A:A),"Pas installé") -> EJ-847-PS | R10: =IF(Q10 = "Pas installé", "Pas installé", IF( Q10<>A10, "Différent du véhicule assigné", "Identique")) -> Identique | S10: =IF(B10 = "", "", VLOOKUP(B10, Commandes!D:G, 4, FALSE)) -> #N/A
A11: CP-304-AD | C11: Carquefou, Pays de la Loire, 44470 | D11: 6 nov. 2024 16:22 | E11: 31 oct. 2024 14:27 | F11: off | G11: - | I11: CP-304-AD | J11: TG Ouest | K11: true | L11: VOLVO | M11: FE | N11: 2013 | O11: YV2VH40A3DB637947 | Q11: =IFERROR(_xlfn.XLOOKUP(B11,'boitiers actifs'!C:C,'boitiers actifs'!A:A),"Pas installé") -> Pas installé | R11: =IF(Q11 = "Pas installé", "Pas installé", IF( Q11<>A11, "Différent du véhicule assigné", "Identique")) -> Pas installé | S11: =IF(B11 = "", "", VLOOKUP(B11, Commandes!D:G, 4, FALSE))
A12: DV-089-QD | C12: Carquefou, Pays de la Loire, 44470 | D12: 24 févr. 2025 16:31 | E12: 24 févr. 2025 16:12 | F12: off | G12: 100 | I12: DV-089-QD | J12: TG Caen (PF) | K12: true | L12: VOLVO | M12: FE | N12: 2015 | O12: YV2V0Y1A3FZ103192 | Q12: =IFERROR(_xlfn.XLOOKUP(B12,'boitiers actifs'!C:C,'boitiers actifs'!A:A),"Pas installé") -> Pas installé | R12: =IF(Q12 = "Pas installé", "Pas installé", IF( Q12<>A12, "Différent du véhicule assigné", "Identique")) -> Pas installé | S12: =IF(B12 = "", "", VLOOKUP(B12, Commandes!D:G, 4, FALSE))
A13: EA-206-DW | B13: GDSE-UXJ-C7X | C13: Caulnes, Bretagne, 22350 | D13: 14 avr. 2026 10:08 | E13: 14 avr. 2026 10:01 | F13: off | G13: - | H13: KASSOURI Drissa | I13: EA-206-DW | J13: TG Rennes (PF) | K13: true | L13: RENAULT | M13: D | N13: 2016 | O13: VF640J562GB003610 | P13: Truck | Q13: =IFERROR(_xlfn.XLOOKUP(B13,'boitiers actifs'!C:C,'boitiers actifs'!A:A),"Pas installé") -> EA-206-DW | R13: =IF(Q13 = "Pas installé", "Pas installé", IF( Q13<>A13, "Différent du véhicule assigné", "Identique")) -> Identique | S13: =IF(B13 = "", "", VLOOKUP(B13, Commandes!D:G, 4, FALSE)) -> oui
A14: FC-613-XX | B14: GMK3-VUC-3E4 | C14: Angers, Pays de la Loire, 49100 | D14: 14 avr. 2026 10:08 | E14: 14 avr. 2026 09:30 | F14: off | G14: 79 | H14: CISSE Mamadou | I14: FC-613-XX | J14: TG Ouest | K14: true | L14: RENAULT | M14: D WIDE | N14: 2019 | O14: VF620J860KB005786 | P14: Truck | Q14: =IFERROR(_xlfn.XLOOKUP(B14,'boitiers actifs'!C:C,'boitiers actifs'!A:A),"Pas installé") -> FC-613-XX | R14: =IF(Q14 = "Pas installé", "Pas installé", IF( Q14<>A14, "Différent du véhicule assigné", "Identique")) -> Identique | S14: =IF(B14 = "", "", VLOOKUP(B14, Commandes!D:G, 4, FALSE)) -> oui
A15: GH-033-QX | B15: GYFP-PJJ-FJF | C15: Carquefou, Pays de la Loire, 44470 | D15: 14 avr. 2026 10:08 | E15: 14 avr. 2026 09:17 | F15: off | G15: 100 | I15: GH-033-QX | J15: TG Ouest | K15: true | L15: RENAULT | M15: T | N15: 2022 | O15: VF611A367ND038308 | P15: Truck | Q15: =IFERROR(_xlfn.XLOOKUP(B15,'boitiers actifs'!C:C,'boitiers actifs'!A:A),"Pas installé") -> GH-033-QX | R15: =IF(Q15 = "Pas installé", "Pas installé", IF( Q15<>A15, "Différent du véhicule assigné", "Identique")) -> Identique | S15: =IF(B15 = "", "", VLOOKUP(B15, Commandes!D:G, 4, FALSE)) -> oui
A16: FA-902-XZ | B16: GMCU-T8J-A9U | C16: Angers, Pays de la Loire, 49051 | D16: 14 avr. 2026 10:08 | E16: On trip | F16: on | G16: 55 | H16: BALDE DIAO Samba | I16: FA-902-XZ | J16: TG Ouest | K16: true | L16: DAF | M16: LF | N16: 2018 | O16: XLRAEL2700L475280 | P16: Truck | Q16: =IFERROR(_xlfn.XLOOKUP(B16,'boitiers actifs'!C:C,'boitiers actifs'!A:A),"Pas installé") -> FA-902-XZ | R16: =IF(Q16 = "Pas installé", "Pas installé", IF( Q16<>A16, "Différent du véhicule assigné", "Identique")) -> Identique | S16: =IF(B16 = "", "", VLOOKUP(B16, Commandes!D:G, 4, FALSE)) -> oui
A17: GH-931-QW | B17: GYHU-FUP-SY9 | C17: Carquefou, Pays de la Loire, 44470 | D17: 14 avr. 2026 10:08 | E17: 14 avr. 2026 08:21 | F17: off | G17: 100 | I17: GH-931-QW | J17: TG Ouest | K17: true | L17: RENAULT | M17: T | N17: 2022 | O17: VF611A365ND038307 | P17: Truck | Q17: =IFERROR(_xlfn.XLOOKUP(B17,'boitiers actifs'!C:C,'boitiers actifs'!A:A),"Pas installé") -> GH-931-QW | R17: =IF(Q17 = "Pas installé", "Pas installé", IF( Q17<>A17, "Différent du véhicule assigné", "Identique")) -> Identique | S17: =IF(B17 = "", "", VLOOKUP(B17, Commandes!D:G, 4, FALSE)) -> oui
A18: ER-911-TW | B18: GGWD-5M4-6UZ | C18: Rennes, Bretagne, 35000 | D18: 14 avr. 2026 10:08 | E18: 14 avr. 2026 09:58 | F18: off | G18: 97 | H18: SANGAND Didier | I18: ER-911-TW | J18: TG Rennes (PF) | K18: true | L18: RENAULT | M18: D | N18: 2017 | O18: VF640J566HB007659 | P18: Truck | Q18: =IFERROR(_xlfn.XLOOKUP(B18,'boitiers actifs'!C:C,'boitiers actifs'!A:A),"Pas installé") -> ER-911-TW | R18: =IF(Q18 = "Pas installé", "Pas installé", IF( Q18<>A18, "Différent du véhicule assigné", "Identique")) -> Identique | S18: =IF(B18 = "", "", VLOOKUP(B18, Commandes!D:G, 4, FALSE)) -> oui
A19: DT-147-VG | C19: Bruguières, Occitanie, 31150 | D19: 30 sept. 2025 17:27 | E19: 30 sept. 2025 16:37 | F19: off | G19: 36 | I19: DT-147-VG | J19: TG MIDI PYRENEES | K19: true | L19: VOLVO | M19: FE | N19: 2015 | O19: YV2V0Y1A5FZ103193 | P19: Truck | Q19: =IFERROR(_xlfn.XLOOKUP(B19,'boitiers actifs'!C:C,'boitiers actifs'!A:A),"Pas installé") -> Pas installé | R19: =IF(Q19 = "Pas installé", "Pas installé", IF( Q19<>A19, "Différent du véhicule assigné", "Identique")) -> Pas installé | S19: =IF(B19 = "", "", VLOOKUP(B19, Commandes!D:G, 4, FALSE))
A20: DX-992-LX | B20: GA6Y-ACC-ZGN | C20: Ploërmel, Bretagne, 56800 | D20: 14 avr. 2026 10:08 | E20: 14 avr. 2026 09:44 | F20: off | G20: 68 | H20: TAANE Sebastien | I20: DX-992-LX | J20: TG St Brieuc (PF) | K20: true | L20: VOLVO | M20: FL | N20: 2015 | O20: YV2T0X1A2FZ103749 | P20: Truck | Q20: =IFERROR(_xlfn.XLOOKUP(B20,'boitiers actifs'!C:C,'boitiers actifs'!A:A),"Pas installé") -> DX-992-LX | R20: =IF(Q20 = "Pas installé", "Pas installé", IF( Q20<>A20, "Différent du véhicule assigné", "Identique")) -> Identique | S20: =IF(B20 = "", "", VLOOKUP(B20, Commandes!D:G, 4, FALSE)) -> oui
A21: DY-586-AV | C21: Carquefou, Pays de la Loire, 44470 | D21: 14 nov. 2025 09:32 | E21: 14 nov. 2025 08:09 | F21: off | G21: 97 | I21: DY-586-AV | J21: TG Ouest | K21: true | L21: RENAULT | M21: D WIDE | N21: 2016 | O21: VF620J868GB001573 | P21: Truck | Q21: =IFERROR(_xlfn.XLOOKUP(B21,'boitiers actifs'!C:C,'boitiers actifs'!A:A),"Pas installé") -> Pas installé | R21: =IF(Q21 = "Pas installé", "Pas installé", IF( Q21<>A21, "Différent du véhicule assigné", "Identique")) -> Pas installé | S21: =IF(B21 = "", "", VLOOKUP(B21, Commandes!D:G, 4, FALSE))
A22: GS-381-DM | B22: GVEY-USU-EYR | C22: Vezin-le-Coquet, Bretagne, 35132 | D22: 14 avr. 2026 10:08 | E22: On trip | F22: on | G22: 81 | H22: DABO GARREAU Melvyn | I22: GS-381-DM | J22: B100, TG Ouest | K22: true | L22: RENAULT | M22: D WIDE | N22: 2023 | O22: VF620J868PB012198 | P22: Truck | Q22: =IFERROR(_xlfn.XLOOKUP(B22,'boitiers actifs'!C:C,'boitiers actifs'!A:A),"Pas installé") -> GS-381-DM | R22: =IF(Q22 = "Pas installé", "Pas installé", IF( Q22<>A22, "Différent du véhicule assigné", "Identique")) -> Identique | S22: =IF(B22 = "", "", VLOOKUP(B22, Commandes!D:G, 4, FALSE)) -> oui
A23: FC-143-XX | B23: GMHZ-WUD-VBH | C23: Asnières-sur-Vègre, Pays de la Loire, 72430 | D23: 14 avr. 2026 10:08 | E23: On trip | F23: on | G23: 64 | H23: DIAWARA Mody | I23: FC-143-XX | J23: TG Ouest | K23: true | L23: RENAULT | M23: D WIDE | N23: 2019 | O23: VF620J861KB005750 | P23: Truck | Q23: =IFERROR(_xlfn.XLOOKUP(B23,'boitiers actifs'!C:C,'boitiers actifs'!A:A),"Pas installé") -> FC-143-XX | R23: =IF(Q23 = "Pas installé", "Pas installé", IF( Q23<>A23, "Différent du véhicule assigné", "Identique")) -> Identique | S23: =IF(B23 = "", "", VLOOKUP(B23, Commandes!D:G, 4, FALSE)) -> oui
A24: ES-540-QB | B24: GHDV-EV2-3N5 | C24: Cherbourg-en-Cotentin, Normandie, 50100 | D24: 14 avr. 2026 10:08 | E24: On trip | F24: on | G24: 46 | H24: SAUDRAIS Jerome | I24: ES-540-QB | J24: TG Caen (PF) | K24: true | L24: RENAULT | M24: D WIDE | N24: 2017 | O24: VF620J864HB004049 | P24: Truck | Q24: =IFERROR(_xlfn.XLOOKUP(B24,'boitiers actifs'!C:C,'boitiers actifs'!A:A),"Pas installé") -> ES-540-QB | R24: =IF(Q24 = "Pas installé", "Pas installé", IF( Q24<>A24, "Différent du véhicule assigné", "Identique")) -> Identique | S24: =IF(B24 = "", "", VLOOKUP(B24, Commandes!D:G, 4, FALSE)) -> oui
A25: EE-387-AM | C25: Carquefou, Pays de la Loire, 44470 | D25: 13 nov. 2025 18:29 | E25: 13 nov. 2025 18:02 | F25: off | G25: 92 | I25: EE-387-AM | J25: TG Ouest | K25: true | L25: RENAULT | M25: D WIDE | N25: 2016 | O25: VF620J864GB002171 | P25: Truck | Q25: =IFERROR(_xlfn.XLOOKUP(B25,'boitiers actifs'!C:C,'boitiers actifs'!A:A),"Pas installé") -> Pas installé | R25: =IF(Q25 = "Pas installé", "Pas installé", IF( Q25<>A25, "Différent du véhicule assigné", "Identique")) -> Pas installé | S25: =IF(B25 = "", "", VLOOKUP(B25, Commandes!D:G, 4, FALSE))
A26: GM-405-VD | B26: GT8Y-ZBH-Y4E | C26: Theix-Noyalo, Bretagne, 56450 | D26: 14 avr. 2026 10:08 | E26: On trip | F26: on | G26: 65 | H26: BAHOLET David | I26: GM-405-VD | J26: TG Ouest | K26: true | L26: RENAULT | M26: D WIDE | N26: 2023 | O26: VF620M863PB006164 | P26: Truck | Q26: =IFERROR(_xlfn.XLOOKUP(B26,'boitiers actifs'!C:C,'boitiers actifs'!A:A),"Pas installé") -> GM-405-VD | R26: =IF(Q26 = "Pas installé", "Pas installé", IF( Q26<>A26, "Différent du véhicule assigné", "Identique")) -> Identique | S26: =IF(B26 = "", "", VLOOKUP(B26, Commandes!D:G, 4, FALSE)) -> oui
A27: EQ-199-DT | B27: GGED-D56-N7K | C27: Villaines-la-Juhel, Pays de la Loire, 53700 | D27: 14 avr. 2026 10:08 | E27: On trip | F27: on | G27: - | H27: OUAHIM Driss | I27: EQ-199-DT | J27: TG Laval (PF) | K27: true | L27: RENAULT | M27: D | N27: 2017 | O27: VF640J567HB007251 | P27: Truck | Q27: =IFERROR(_xlfn.XLOOKUP(B27,'boitiers actifs'!C:C,'boitiers actifs'!A:A),"Pas installé") -> EQ-199-DT | R27: =IF(Q27 = "Pas installé", "Pas installé", IF( Q27<>A27, "Différent du véhicule assigné", "Identique")) -> Identique | S27: =IF(B27 = "", "", VLOOKUP(B27, Commandes!D:G, 4, FALSE)) -> oui
A28: EZ-411-LJ | B28: GKYW-FP2-N2G | C28: Givrand, Pays de la Loire, 85800 | D28: 14 avr. 2026 10:08 | E28: On trip | F28: off | G28: 56 | H28: BAH Mamadou Sadio | I28: EZ-411-LJ | J28: TG Ouest | K28: true | L28: VOLVO | M28: FE | N28: 2018 | O28: YV2V0Y1A4JZ120155 | P28: Truck | Q28: =IFERROR(_xlfn.XLOOKUP(B28,'boitiers actifs'!C:C,'boitiers actifs'!A:A),"Pas installé") -> EZ-411-LJ | R28: =IF(Q28 = "Pas installé", "Pas installé", IF( Q28<>A28, "Différent du véhicule assigné", "Identique")) -> Identique | S28: =IF(B28 = "", "", VLOOKUP(B28, Commandes!D:G, 4, FALSE)) -> oui
A29: FZ-365-XF | B29: GZD9-V8G-WMG | C29: Carquefou, Pays de la Loire, 44470 | D29: 14 avr. 2026 10:08 | E29: 10 avr. 2026 21:11 | F29: off | G29: 26 | I29: FZ-365-XF | J29: TG Ouest | K29: true | L29: IVECO | M29: DAILY | N29: 2021 | O29: ZCFCH35A20D682907 | P29: Truck | Q29: =IFERROR(_xlfn.XLOOKUP(B29,'boitiers actifs'!C:C,'boitiers actifs'!A:A),"Pas installé") -> FZ-365-XF | R29: =IF(Q29 = "Pas installé", "Pas installé", IF( Q29<>A29, "Différent du véhicule assigné", "Identique")) -> Identique | S29: =IF(B29 = "", "", VLOOKUP(B29, Commandes!D:G, 4, FALSE)) -> oui
A30: FQ-538-ZT | B30: GMXY-V8C-68J | C30: Vannes, Bretagne, 56000 | D30: 14 avr. 2026 10:08 | E30: On trip | F30: on | G30: 57 | H30: DA ROCHA Fernando | I30: FQ-538-ZT | J30: TG Quimper (PF) | K30: true | L30: RENAULT | M30: D WIDE | N30: 2020 | O30: VF620J860LB007975 | P30: Truck | Q30: =IFERROR(_xlfn.XLOOKUP(B30,'boitiers actifs'!C:C,'boitiers actifs'!A:A),"Pas installé") -> FQ-538-ZT | R30: =IF(Q30 = "Pas installé", "Pas installé", IF( Q30<>A30, "Différent du véhicule assigné", "Identique")) -> Identique | S30: =IF(B30 = "", "", VLOOKUP(B30, Commandes!D:G, 4, FALSE)) -> oui
A31: DL-782-CT | C31: Carquefou, Pays de la Loire, 44470 | D31: 29 déc. 2025 12:01 | E31: 29 déc. 2025 11:32 | F31: off | G31: 60 | I31: DL-782-CT | J31: TG Ouest | K31: true | L31: RENAULT | M31: D | N31: 2015 | O31: VF640J862FB000488 | P31: Truck | Q31: =IFERROR(_xlfn.XLOOKUP(B31,'boitiers actifs'!C:C,'boitiers actifs'!A:A),"Pas installé") -> Pas installé | R31: =IF(Q31 = "Pas installé", "Pas installé", IF( Q31<>A31, "Différent du véhicule assigné", "Identique")) -> Pas installé | S31: =IF(B31 = "", "", VLOOKUP(B31, Commandes!D:G, 4, FALSE))
A32: FR-723-EP | B32: GR9P-FB6-XWY | C32: Carquefou, Pays de la Loire, 44470 | D32: 14 avr. 2026 10:08 | E32: 14 avr. 2026 10:01 | F32: off | G32: 47 | H32: HEDOUIN Laurent | I32: FR-723-EP | J32: TG Ouest | K32: true | L32: RENAULT | M32: D | N32: 2020 | O32: VF640J563LB014805 | P32: Truck | Q32: =IFERROR(_xlfn.XLOOKUP(B32,'boitiers actifs'!C:C,'boitiers actifs'!A:A),"Pas installé") -> FR-723-EP | R32: =IF(Q32 = "Pas installé", "Pas installé", IF( Q32<>A32, "Différent du véhicule assigné", "Identique")) -> Identique | S32: =IF(B32 = "", "", VLOOKUP(B32, Commandes!D:G, 4, FALSE)) -> oui
A33: DX-219-JR | C33: Carquefou, Pays de la Loire, 44470 | D33: 14 nov. 2025 09:24 | E33: 14 nov. 2025 08:03 | F33: off | G33: 48 | I33: DX-219-JR | J33: TG Rennes (PF) | K33: true | L33: RENAULT | M33: D WIDE | N33: 2015 | O33: VF620J866FB001411 | P33: Truck | Q33: =IFERROR(_xlfn.XLOOKUP(B33,'boitiers actifs'!C:C,'boitiers actifs'!A:A),"Pas installé") -> Pas installé | R33: =IF(Q33 = "Pas installé", "Pas installé", IF( Q33<>A33, "Différent du véhicule assigné", "Identique")) -> Pas installé | S33: =IF(B33 = "", "", VLOOKUP(B33, Commandes!D:G, 4, FALSE))
A34: EZ-361-HN | B34: GJWC-92S-7EH | C34: Pacé, Bretagne, 35740 | D34: 14 avr. 2026 10:08 | E34: On trip | F34: on | G34: 76 | H34: TILLY Frederic | I34: EZ-361-HN | J34: TG St Brieuc (PF) | K34: true | L34: VOLVO | M34: FE | N34: 2018 | O34: YV2V0Y1A2JZ120185 | P34: Truck | Q34: =IFERROR(_xlfn.XLOOKUP(B34,'boitiers actifs'!C:C,'boitiers actifs'!A:A),"Pas installé") -> EZ-361-HN | R34: =IF(Q34 = "Pas installé", "Pas installé", IF( Q34<>A34, "Différent du véhicule assigné", "Identique")) -> Identique | S34: =IF(B34 = "", "", VLOOKUP(B34, Commandes!D:G, 4, FALSE)) -> oui
A35: ER-129-QA | B35: GGJW-7C9-U2X | C35: Rennes, Bretagne, 35000 | D35: 14 avr. 2026 10:08 | E35: On trip | F35: on | G35: 93 | H35: CHEVALIER Christophe | I35: ER-129-QA | J35: TG Rennes (PF) | K35: true | L35: RENAULT | M35: D | N35: 2018 | O35: VF640J562JB007759 | P35: Truck | Q35: =IFERROR(_xlfn.XLOOKUP(B35,'boitiers actifs'!C:C,'boitiers actifs'!A:A),"Pas installé") -> ER-129-QA | R35: =IF(Q35 = "Pas installé", "Pas installé", IF( Q35<>A35, "Différent du véhicule assigné", "Identique")) -> Identique | S35: =IF(B35 = "", "", VLOOKUP(B35, Commandes!D:G, 4, FALSE)) -> oui
A36: GR-728-QJ | B36: GVCB-JXY-JTK | C36: Vertou, Pays de la Loire, 44120 | D36: 14 avr. 2026 10:08 | E36: 14 avr. 2026 09:59 | F36: off | G36: 94 | H36: RIMAJOU Arnaud | I36: GR-728-QJ | J36: B100, TG Ouest | K36: true | L36: RENAULT | M36: D WIDE | N36: 2023 | O36: VF620J862PB012214 | P36: Truck | Q36: =IFERROR(_xlfn.XLOOKUP(B36,'boitiers actifs'!C:C,'boitiers actifs'!A:A),"Pas installé") -> GR-728-QJ | R36: =IF(Q36 = "Pas installé", "Pas installé", IF( Q36<>A36, "Différent du véhicule assigné", "Identique")) -> Identique | S36: =IF(B36 = "", "", VLOOKUP(B36, Commandes!D:G, 4, FALSE)) -> oui
A37: FQ-217-ZT | B37: GMVJ-F7H-EBY | C37: Quimperlé, Bretagne, 29300 | D37: 14 avr. 2026 10:08 | E37: 14 avr. 2026 10:02 | F37: on | G37: 85 | H37: HERRI Denis | I37: FQ-217-ZT | J37: TG Quimper (PF) | K37: true | L37: RENAULT | M37: D WIDE | N37: 2020 | O37: VF620J869LB007974 | P37: Truck | Q37: =IFERROR(_xlfn.XLOOKUP(B37,'boitiers actifs'!C:C,'boitiers actifs'!A:A),"Pas installé") -> FQ-217-ZT | R37: =IF(Q37 = "Pas installé", "Pas installé", IF( Q37<>A37, "Différent du véhicule assigné", "Identique")) -> Identique | S37: =IF(B37 = "", "", VLOOKUP(B37, Commandes!D:G, 4, FALSE)) -> oui
A38: GH-097-QX | B38: GYG6-GW2-PXF | C38: Carquefou, Pays de la Loire, 44470 | D38: 14 avr. 2026 10:08 | E38: 14 avr. 2026 08:48 | F38: off | G38: 100 | I38: GH-097-QX | J38: TG Ouest | K38: true | L38: RENAULT | M38: T | N38: 2022 | O38: VF611A364ND038914 | P38: Truck | Q38: =IFERROR(_xlfn.XLOOKUP(B38,'boitiers actifs'!C:C,'boitiers actifs'!A:A),"Pas installé") -> GH-097-QX | R38: =IF(Q38 = "Pas installé", "Pas installé", IF( Q38<>A38, "Différent du véhicule assigné", "Identique")) -> Identique | S38: =IF(B38 = "", "", VLOOKUP(B38, Commandes!D:G, 4, FALSE)) -> oui
A39: FP-060-JA | C39: Carquefou, Pays de la Loire, 44470 | D39: 29 déc. 2025 11:03 | E39: 29 déc. 2025 10:32 | F39: off | G39: 96 | I39: FP-060-JA | J39: TG Ouest | K39: true | L39: RENAULT | M39: D WIDE | N39: 2020 | O39: VF620M862LB003945 | P39: Truck | Q39: =IFERROR(_xlfn.XLOOKUP(B39,'boitiers actifs'!C:C,'boitiers actifs'!A:A),"Pas installé") -> Pas installé | R39: =IF(Q39 = "Pas installé", "Pas installé", IF( Q39<>A39, "Différent du véhicule assigné", "Identique")) -> Pas installé | S39: =IF(B39 = "", "", VLOOKUP(B39, Commandes!D:G, 4, FALSE))
A40: CN-390-WD | C40: Couffé, Pays de la Loire, 44521 | D40: 3 oct. 2024 12:38 | E40: 3 oct. 2024 12:34 | F40: off | G40: 75 | I40: CN-390-WD | J40: TG Ouest | K40: true | L40: RENAULT | M40: D WIDE | N40: 2024 | O40: VF620J868RB013709 | P40: Automatic | Q40: =IFERROR(_xlfn.XLOOKUP(B40,'boitiers actifs'!C:C,'boitiers actifs'!A:A),"Pas installé") -> Pas installé | R40: =IF(Q40 = "Pas installé", "Pas installé", IF( Q40<>A40, "Différent du véhicule assigné", "Identique")) -> Pas installé | S40: =IF(B40 = "", "", VLOOKUP(B40, Commandes!D:G, 4, FALSE))
...

Sheet Véhicules Samsara non équipés
A1: Last Connected | B1: (Plusieurs éléments)
A2: Différents | B2: Pas installé
A4: Site | B4: Nombre de véhicules non équipé
A5: EUR Schiltigheim LIV
A6: ED-783-HE | B6: 1
A7: Site Bonneville
A8: EZ-838-EL | B8: 1
A9: Site St Loubes, TEST TEMPERATURE , TG AQUITAINE
A10: GL-338-WD | B10: 1
A11: GX-879-NT | B11: 1
A12: HA-458-ZM | B12: 1
A13: HA-582-GC | B13: 1
A14: Site St Loubes, TG AQUITAINE
A15: FD-972-ZS | B15: 1
A16: TG Arques, TG NORD
A17: EV-563-PW | B17: 1
A18: EV-575-PW | B18: 1
A19: FQ-575-KG | B19: 1
A20: TG BOURGOGNE
A21: EF-734-XN | B21: 1
A22: EQ-229-KN | B22: 1
A23: TG CENTRE EST
A24: DW-773-YG | B24: 1
A25: TG CENTRE OUEST
A26: DX-801-EY | B26: 1
A27: DX-836-BJ | B27: 1
A28: TG COULOMMIERS
A29: HH-714-FQ | B29: 1
A30: TG IDF VALENTON
A31: DV-919-PS | B31: 1
A32: EE-280-ZV | B32: 1
A33: FB-980-TY | B33: 1
A34: FF-956-RQ | B34: 1
A35: FG-129-HR | B35: 1
A36: FG-725-GA | B36: 1
A37: TG Le Muy (PF)
A38: DH-914-WC | B38: 1
A39: EF-068-CH | B39: 1
A40: FN-765-KB | B40: 1
A41: GW-007-FJ | B41: 1
...

Sheet Parc Avril
A1: Etablissement opérationnel | B1: Famille | C1: Parc | D1: Code parc interne | E1: Immatriculation | F1: Sous-famille | G1: Segment | H1: Marque | I1: Modèle | J1: Version | K1: Date de mise en service | L1: Date d'entrée | M1: Date de retrait | N1: Mode d'acquisition | O1: Fournisseur | P1: Conducteur | Q1: Dernier index compteur connu | R1: Date dernier index connu | S1: Libellé statut | T1: N° de série | U1: P.T.A.C | V1: Energie | W1: CO2 | X1: Puissance fiscale | Y1: Catégorie du véhicule (CE) | Z1: Boitier
A2: COFIDA I4 | B2: VP | C2: SITE RUNGIS I4 | D2: GR108DK | E2: GR-108-DK | F2: Berline | G2: 2 | H2: RENAULT | I2: CLIO 5 EVOLUTION | J2: TCE 90 | K2: 12/09/2023 | L2: 21/09/2023 17:30 | N2: Achat neuf | O2: TRANSGOURMET | P2: LOUYEBO THEMARK | Q2: 50461 | R2: 11/12/2025 12:41 | S2: En exploitation | T2: VF1RJA00371030784 | U2: 1595 | V2: Essence | W2: 120 | X2: 5 | Y2: M1 | Z2: =_xlfn.XLOOKUP(E2, Commandes!F:F, Commandes!D:D) -> #N/A
A3: COFIDA I4 | B3: VP | C3: SITE RUNGIS I4 | D3: GR783XM | E3: GR-783-XM | F3: Berline | G3: 4 | H3: CITROEN | I3: C4 | J3: PureTech 130 S&S EAT8 Shine | K3: 19/10/2023 | L3: 25/10/2023 10:30 | N3: Achat neuf | O3: TRANSGOURMET | P3: DUHAMEL ELISE | Q3: 40129 | R3: 23/02/2026 11:58 | S3: En exploitation | T3: VR7BAHNSBPE067192 | U3: 1755 | V3: Essence | W3: 130 | X3: 7 | Y3: M1 | Z3: =_xlfn.XLOOKUP(E3, Commandes!F:F, Commandes!D:D) -> #N/A
